Traceback (most recent call last):
  File "../../../../train_semi.py", line 23, in <module>
    from u2pl.utils.loss_helper import ( compute_contra_memobank_loss, compute_unsupervised_loss,get_criterion,)
  File "/home/jidian/sdb1/jinlei/U2PL/u2pl/utils/loss_helper.py", line 7, in <module>
    from .utils import dequeue_and_enqueue
  File "/home/jidian/sdb1/jinlei/U2PL/u2pl/utils/utils.py", line 13, in <module>
    from skimage.measure import label, regionprops
ModuleNotFoundError: No module named 'skimage'
Traceback (most recent call last):
  File "/home/jidian/anaconda3/envs/u2pl/lib/python3.6/runpy.py", line 193, in _run_module_as_main
    "__main__", mod_spec)
  File "/home/jidian/anaconda3/envs/u2pl/lib/python3.6/runpy.py", line 85, in _run_code
    exec(code, run_globals)
  File "/home/jidian/anaconda3/envs/u2pl/lib/python3.6/site-packages/torch/distributed/launch.py", line 260, in <module>
    main()
  File "/home/jidian/anaconda3/envs/u2pl/lib/python3.6/site-packages/torch/distributed/launch.py", line 256, in main
    cmd=cmd)
subprocess.CalledProcessError: Command '['/home/jidian/anaconda3/envs/u2pl/bin/python', '-u', '../../../../train_semi.py', '--local_rank=0', '--config=config1.yaml', '--seed', '2', '--port', '1255']' returned non-zero exit status 1.
